[2022-12-25 16:09:30,224: ERROR/MainProcess] Received unregistered task of type 'src.celery.setup_celery.wellcome'.
The message has been ignored and discarded.

Did you remember to import the module containing this task?
Or maybe you're using relative imports?

Please see
http://docs.celeryq.org/en/latest/internals/protocol.html
for more information.

The full contents of the message body was:
b'[[], {}, {"callbacks": null, "errbacks": null, "chain": null, "chord": null}]' (77b)

Thw full contents of the message headers:
{'lang': 'py', 'task': 'src.celery.setup_celery.wellcome', 'id': '335a9d93-04c4-43d6-9690-4fea156b746b', 'shadow': None, 'eta': None, 'expires': None, 'group': None, 'group_index': None, 'retries': 0, 'timelimit': [None, None], 'root_id': '335a9d93-04c4-43d6-9690-4fea156b746b', 'parent_id': None, 'argsrepr': '()', 'kwargsrepr': '{}', 'origin': 'gen1151445@lab01', 'ignore_result': False}

The delivery info for this task is:
{'exchange': '', 'routing_key': 'celery'}
Traceback (most recent call last):
  File "/home/tynp/demo_stack/fastapi_mongo_redis_celery_template/venv/lib/python3.10/site-packages/celery/worker/consumer/consumer.py", line 591, in on_task_received
    strategy = strategies[type_]
KeyError: 'src.celery.setup_celery.wellcome'
[2022-12-25 16:10:00,007: ERROR/MainProcess] Received unregistered task of type 'src.celery.setup_celery.wellcome'.
The message has been ignored and discarded.

Did you remember to import the module containing this task?
Or maybe you're using relative imports?

Please see
http://docs.celeryq.org/en/latest/internals/protocol.html
for more information.

The full contents of the message body was:
b'[[], {}, {"callbacks": null, "errbacks": null, "chain": null, "chord": null}]' (77b)

Thw full contents of the message headers:
{'lang': 'py', 'task': 'src.celery.setup_celery.wellcome', 'id': '7f60d39d-9c8c-4f80-9ac1-5ed7ca8186b1', 'shadow': None, 'eta': None, 'expires': None, 'group': None, 'group_index': None, 'retries': 0, 'timelimit': [None, None], 'root_id': '7f60d39d-9c8c-4f80-9ac1-5ed7ca8186b1', 'parent_id': None, 'argsrepr': '()', 'kwargsrepr': '{}', 'origin': 'gen1151445@lab01', 'ignore_result': False}

The delivery info for this task is:
{'exchange': '', 'routing_key': 'celery'}
Traceback (most recent call last):
  File "/home/tynp/demo_stack/fastapi_mongo_redis_celery_template/venv/lib/python3.10/site-packages/celery/worker/consumer/consumer.py", line 591, in on_task_received
    strategy = strategies[type_]
KeyError: 'src.celery.setup_celery.wellcome'
[2022-12-25 16:10:41,221: WARNING/MainProcess] Exception ignored in atexit callback
[2022-12-25 16:10:41,221: WARNING/MainProcess] : 
[2022-12-25 16:10:41,221: WARNING/MainProcess] <function _exit_function at 0x7f69e79c1f30>
[2022-12-25 16:10:41,221: WARNING/MainProcess] Traceback (most recent call last):
[2022-12-25 16:10:41,221: WARNING/MainProcess]   File "/usr/local/lib/python3.10/multiprocessing/util.py", line 334, in _exit_function
[2022-12-25 16:10:41,222: WARNING/MainProcess]     
[2022-12-25 16:10:41,222: WARNING/MainProcess] _run_finalizers(0)
[2022-12-25 16:10:41,222: WARNING/MainProcess]   File "/usr/local/lib/python3.10/multiprocessing/util.py", line 300, in _run_finalizers
[2022-12-25 16:10:41,222: WARNING/MainProcess]     
[2022-12-25 16:10:41,222: WARNING/MainProcess] finalizer()
[2022-12-25 16:10:41,222: WARNING/MainProcess]   File "/usr/local/lib/python3.10/multiprocessing/util.py", line 224, in __call__
[2022-12-25 16:10:41,222: WARNING/MainProcess]     
[2022-12-25 16:10:41,223: WARNING/MainProcess] res = self._callback(*self._args, **self._kwargs)
[2022-12-25 16:10:41,223: WARNING/MainProcess]   File "/home/tynp/demo_stack/fastapi_mongo_redis_celery_template/venv/lib/python3.10/site-packages/billiard/pool.py", line 1662, in _terminate_pool
[2022-12-25 16:10:41,223: WARNING/MainProcess]     
[2022-12-25 16:10:41,223: WARNING/MainProcess] cls._help_stuff_finish(*help_stuff_finish_args)
[2022-12-25 16:10:41,223: WARNING/MainProcess]   File "/home/tynp/demo_stack/fastapi_mongo_redis_celery_template/venv/lib/python3.10/site-packages/celery/concurrency/asynpool.py", line 1341, in _help_stuff_finish
[2022-12-25 16:10:41,224: WARNING/MainProcess]     
[2022-12-25 16:10:41,224: WARNING/MainProcess] readable, _, again = _select(inqR, timeout=0.5)
[2022-12-25 16:10:41,224: WARNING/MainProcess]   File "/home/tynp/demo_stack/fastapi_mongo_redis_celery_template/venv/lib/python3.10/site-packages/celery/concurrency/asynpool.py", line 165, in _select
[2022-12-25 16:10:41,224: WARNING/MainProcess]     
[2022-12-25 16:10:41,224: WARNING/MainProcess] return poll(readers, writers, err, timeout)
[2022-12-25 16:10:41,224: WARNING/MainProcess]   File "/home/tynp/demo_stack/fastapi_mongo_redis_celery_template/venv/lib/python3.10/site-packages/celery/concurrency/asynpool.py", line 121, in _select_imp
[2022-12-25 16:10:41,224: WARNING/MainProcess]     
[2022-12-25 16:10:41,224: WARNING/MainProcess] events = poller.poll(timeout)
[2022-12-25 16:10:41,224: WARNING/MainProcess]   File "/home/tynp/demo_stack/fastapi_mongo_redis_celery_template/venv/lib/python3.10/site-packages/celery/apps/worker.py", line 299, in _handle_request
[2022-12-25 16:10:41,225: WARNING/MainProcess]     
[2022-12-25 16:10:41,225: WARNING/MainProcess] raise exc(exitcode)
[2022-12-25 16:10:41,225: WARNING/MainProcess] celery.exceptions
[2022-12-25 16:10:41,225: WARNING/MainProcess] .
[2022-12-25 16:10:41,225: WARNING/MainProcess] WorkerTerminate
[2022-12-25 16:10:41,225: WARNING/MainProcess] : 
[2022-12-25 16:10:41,225: WARNING/MainProcess] 1
[2022-12-25 16:11:00,011: ERROR/MainProcess] Received unregistered task of type 'src.celery.setup_celery.wellcome'.
The message has been ignored and discarded.

Did you remember to import the module containing this task?
Or maybe you're using relative imports?

Please see
http://docs.celeryq.org/en/latest/internals/protocol.html
for more information.

The full contents of the message body was:
b'[[], {}, {"callbacks": null, "errbacks": null, "chain": null, "chord": null}]' (77b)

Thw full contents of the message headers:
{'lang': 'py', 'task': 'src.celery.setup_celery.wellcome', 'id': '23751f9a-7567-4cf9-ba51-fa9bc25c85ee', 'shadow': None, 'eta': None, 'expires': None, 'group': None, 'group_index': None, 'retries': 0, 'timelimit': [None, None], 'root_id': '23751f9a-7567-4cf9-ba51-fa9bc25c85ee', 'parent_id': None, 'argsrepr': '()', 'kwargsrepr': '{}', 'origin': 'gen1151445@lab01', 'ignore_result': False}

The delivery info for this task is:
{'exchange': '', 'routing_key': 'celery'}
Traceback (most recent call last):
  File "/home/tynp/demo_stack/fastapi_mongo_redis_celery_template/venv/lib/python3.10/site-packages/celery/worker/consumer/consumer.py", line 591, in on_task_received
    strategy = strategies[type_]
KeyError: 'src.celery.setup_celery.wellcome'
